Workbook
Name ACTION: #REF!
Name Z_2C0D9096_8D85_462A_A9B5_0B488ADB4269_.wvu.Cols: 'Create Facility'!$E:$E
Name Z_2C0D9096_8D85_462A_A9B5_0B488ADB4269_.wvu.Cols: Login!$E:$E
Name Z_2C0D9096_8D85_462A_A9B5_0B488ADB4269_.wvu.Cols: 'Update Facility'!$E:$E
Name Z_2C0D9096_8D85_462A_A9B5_0B488ADB4269_.wvu.Cols: 'Update Profile'!$E:$E
Name Z_2C0D9096_8D85_462A_A9B5_0B488ADB4269_.wvu.PrintArea: 'Test Report'!$A:$I
Name Z_6F1DCD5D_5DAC_4817_BF40_2B66F6F593E6_.wvu.Cols: 'Create Facility'!$E:$E
Name Z_6F1DCD5D_5DAC_4817_BF40_2B66F6F593E6_.wvu.Cols: Login!$E:$E
Name Z_6F1DCD5D_5DAC_4817_BF40_2B66F6F593E6_.wvu.Cols: 'Update Facility'!$E:$E
Name Z_6F1DCD5D_5DAC_4817_BF40_2B66F6F593E6_.wvu.Cols: 'Update Profile'!$E:$E
Name Z_6F1DCD5D_5DAC_4817_BF40_2B66F6F593E6_.wvu.PrintArea: 'Test Report'!$A:$I
Name Z_BE54E0AD_3725_4423_92D7_4F1C045BE1BC_.wvu.Cols: 'Create Facility'!$E:$E
Name Z_BE54E0AD_3725_4423_92D7_4F1C045BE1BC_.wvu.Cols: Login!$E:$E
Name Z_BE54E0AD_3725_4423_92D7_4F1C045BE1BC_.wvu.Cols: 'Update Facility'!$E:$E
Name Z_BE54E0AD_3725_4423_92D7_4F1C045BE1BC_.wvu.Cols: 'Update Profile'!$E:$E
Name Z_BE54E0AD_3725_4423_92D7_4F1C045BE1BC_.wvu.PrintArea: 'Test Report'!$A:$I

Sheet Guidleline
A1: Guideline to make and understand Unit Test Case
A3: 1. Overview
A4: - In the template, Unit test cases are based on functions. Each sheet presents test cases for one function.
A5: - Cover: General information of the project and Unit Test cases
A6: - FunctionList: The list of Classes and Functions in the document. + To control that the number of Unit TC meets customer's requirement or the norm, user should fill value for 'Normal number of Test cases/KLOC'.
A7: + Click on Function link to open the related Test cases of the function. Note: You should create new Function sheet before creating the link
A8: - Test Report: provive the overview results of Functions Unit test: Test coverage, Test successful coverage (Summary, for normal/abnormal/boundary cases)
A9: Note: Should check the formula of "Sub Total" if you add more functions
A11: 2. Content in Test function sheet
A12: 2.1 Combination of test cases.
A13: - To verify that number of Unit TC meets customer's requirement or not. User has to fill number LOC of tested function and fill value of 'Normal number test cases/KLOC' item in FunctionList sheet, which is required by customer or normal value. The number of lacked TC is shown in 'Lack of test cases' item.
A14: - If the number of Unit TC does not meet the requirement, creator should explain the reasons.
... A47: - Test requirement: Brief description about requirements which are tested in this function, it is not mandatory.

Sheet Cover
B2: UNIT TEST CASE
A4: Project Name | B4: <Facilities Management System> | E4: Creator | F4: KietHT
A5: Project Code | B5: <FMS> | E5: Reviewer/Approver | F5: Group 3
A6: Document Code | B6: =B5&"_"&"UnitTest"&"_"&"v1.0" -> <FMS>_UnitTest_v1.0 | E6: Issue Date | F6: <25/10/2024>
E7: Version | F7: 1
A10: Record of change
A11: Effective Date | B11: Version | C11: Change Item | D11: *A,D,M | E11: Change description | F11: Reference
A12: 45590 | B12: 1.0 | C12: Cover, FunctionList, Login | D12: A | E12: Add cover, FunctionList, Unit test for login
A13: 45602 | B13: 1.0 | C13: Update Profile, Create Facility | D13: A | E13: Add unit test for update profile and create facility

Sheet FunctionList
E2: UNIT TEST CASE LIST
A4: Project Name | E4: =Cover!B4 -> <Facilities Management System>
A5: Project Code | E5: =Cover!B5 -> <FMS>
A6: Normal number of Test cases/KLOC | E6: 29
A7: Test Environment Setup Description | E7: <List enviroment requires in this system 1. Server 2. Database 3. Web Browser >
A10: No | B10: Requirement Name | C10: Class Name | D10: Function Name | E10: Function Code(Optional) | F10: Sheet Name | G10: Description | H10: Pre-Condition
A11: 1 | C11: Login | D11: Login | E11: Login | F11: Login
A12: 2 | C12: User Profile | D12: Update Profile | E12: Update Profile | F12: Update Profile
A13: 3 | C13: Facility | D13: Create Facility | E13: Create Facility | F13: Create Facility
A14: 4 | C14: Facility | D14: Update Facility | E14: Update Facility | F14: Update Facility

Sheet Test Report
A2: UNIT TEST REPORT
A4: Project Name | B4: =Cover!B4 -> <Facilities Management System> | D4: Creator | F4: KietHT
A5: Project Code | B5: =Cover!B5 -> <FMS> | D5: Reviewer/Approver | F5: G3
A6: Document Code | B6: =B5&"_"&"Test Report"&"_"&"v1.0" -> <FMS>_Test Report_v1.0 | D6: Issue Date | F6: 45590
A7: Notes
A11: No | B11: Function code | C11: Passed | D11: Failed | E11: Untested | F11: N | G11: A | H11: B | I11: Total Test Cases
A12: 1 | B12: Login | C12: =Login!A7 -> 3 | D12: =Login!C7 -> 0 | E12: =Login!F7 -> 0 | F12: =Login!L7 -> 1 | G12: =Login!M7 -> 2 | H12: =Login!N7 -> 0 | I12: =Login!O7 -> 3
A13: 2 | B13: Update Profile | C13: ='Update Profile'!A7 -> 9 | D13: ='Update Profile'!C7 -> 1 | E13: ='Update Profile'!F7 -> 0 | F13: ='Update Profile'!L7 -> 2 | G13: ='Update Profile'!M7 -> 2 | H13: ='Update Profile'!N7 -> 6 | I13: ='Update Profile'!O7 -> 10
A14: 3 | B14: Create Faciilities | C14: ='Create Facility'!A7 -> 6 | D14: ='Create Facility'!C7 -> 2 | E14: ='Create Facility'!F7 -> 0 | F14: ='Create Facility'!L7 -> 2 | G14: ='Create Facility'!M7 -> 6 | H14: ='Create Facility'!N7 -> 0 | I14: ='Create Facility'!O7 -> 8
A15: 4 | B15: Update Facility | C15: 7 | D15: 1 | E15: 0 | F15: 1 | G15: 4 | H15: 3 | I15: 8
B17: Sub total | C17: =SUM(C10:C16) -> 25 | D17: =SUM(D10:D16) -> 4 | E17: =SUM(E10:E16) -> 0 | F17: =SUM(F10:F16) -> 6 | G17: =SUM(G10:G16) -> 14 | H17: =SUM(H10:H16) -> 9 | I17: =SUM(I10:I16) -> 29
B19: Test coverage | D19: =(C17+D17)*100/(I17) -> 100 | E19: %
B20: Test successful coverage | D20: =C17*100/(I17) -> 86.206897 | E20: %
B21: Normal case | D21: =F17*100/I17 -> 20.689655 | E21: %
B22: Abnormal case | D22: =G17*100/I17 -> 48.275862 | E22: %
B23: Boundary case | D23: =H17*100/I17 -> 31.034483 | E23: %

Sheet Login
A2: Function Code | C2: =FunctionList!E11 -> Login | F2: Function Name | L2: =FunctionList!D11 -> Login
A3: Created By | C3: KietHT | F3: Executed By | L3: KietHT
A4: Lines of code | C4: 100 | F4: Lack of test cases | L4: =IF(FunctionList!E6<>"N/A",SUM(C4*FunctionList!E6/1000,-O7),"N/A") -> -0.1
A5: Test requirement
A6: Passed | C6: Failed | F6: Untested | L6: N/A/B | O6: Total Test Cases
A7: =COUNTIF(F31:HQ31,"P") -> 3 | C7: =COUNTIF(F31:HQ31,"F") -> 0 | F7: =SUM(O7,-A7,-C7) -> 0 | L7: =COUNTIF(E30:HQ30,"N") -> 1 | M7: =COUNTIF(E30:HQ30,"A") -> 2 | N7: =COUNTIF(E30:HQ30,"B") -> 0 | O7: =COUNTA(E9:HT9) -> 3
F9: UTCID01 | G9: UTCID02 | H9: UTCID03
A10: Condition | B10: Precondition
D11: Can connect with server | F11: O | G11: O | H11: O
D12: Already have email | F12: O | G12: O | H12: O
B14: Email
D15: FPT email | F15: O | H15: O
D16: Normal email | G16: O
B17: Status
D18: 0 | H18: O
D19: 1 | F19: O
A21: Confirm | B21: Return
D22: T | F22: O
D23: F | G23: O | H23: O
B24: Exception
B26: Log message
D27: "login successfully" | F27: O
B28: "you have to login with FPT email" | G28: O
D29: "Account has ban ! " | H29: O
A30: Result | B30: Type(N : Normal, A : Abnormal, B : Boundary) | F30: N | G30: A | H30: A
B31: Passed/Failed | F31: P | G31: P | H31: P
B32: Executed Date | F32: 45590 | G32: 45590 | H32: 45590
B33: Defect ID

Sheet Update Profile
A2: Function Code | C2: =FunctionList!E12 -> Update Profile | F2: Function Name | L2: =FunctionList!D12 -> Update Profile
A3: Created By | C3: KietHT | F3: Executed By | L3: KietHT
A4: Lines of code | C4: 300 | F4: Lack of test cases | L4: =IF(FunctionList!E6<>"N/A",SUM(C4*FunctionList!E6/1000,-O7),"N/A") -> -1.3
A5: Test requirement | C5: <Brief description about requirements which are tested in this function>
A6: Passed | C6: Failed | F6: Untested | L6: N/A/B | O6: Total Test Cases
A7: =COUNTIF(F43:HQ43,"P") -> 9 | C7: =COUNTIF(F43:HQ43,"F") -> 1 | F7: =SUM(O7,-A7,-C7) -> 0 | L7: =COUNTIF(E42:HQ42,"N") -> 2 | M7: =COUNTIF(E42:HQ42,"A") -> 2 | N7: =COUNTIF(E42:HQ42,"B") -> 6 | O7: =COUNTA(E9:HT9) -> 10
F9: UTCID01 | G9: UTCID02 | H9: UTCID03 | I9: UTCID04 | J9: UTCID05 | K9: UTCID06 | L9: UTCID07 | M9: UTCID08 | N9: UTCID09 | O9: UTCID10
A10: Condition | B10: Precondition
D11: Can connect with server | F11: O | G11: O | H11: O | I11: O | J11: O | K11: O | L11: O | M11: O | N11: O | O11: O
D12: User's detail is loaded | F12: O | G12: O | H12: O | I12: O | J12: O | K12: O | L12: O | M12: O | N12: O | O12: O
B14: Tên (tối đa 100 ký tự, k cho ký tự đặc biệt)
D15: "Đặng Quế Anh" | F15: O | K15: O | L15: O | M15: O | N15: O | O15: O
D16: 100 ký tự | G16: O
D17: 101 ký tự | H17: O
D18: "" | I18: O
D19: "Nguyễn*Anh Tú" | J19: O
B20: Địa chỉ (1000 Ký tự)
D21: 1000 ký tự | K21: O
D22: 1001 ký tự | L22: O
D23: thôn 2, Kim Bông - Tân Xã - Thạch Thất | F23: O | G23: O | H23: O | I23: O | J23: O | M23: O | N23: O | O23: O
B24: Số điện thoại (10 số, bắt đầu bằng số 0 )
D25: "0968044126" | F25: O | G25: O | H25: O | I25: O | J25: O | K25: O | L25: O
D26: "1234567890" | M26: O
D27: "11111111111" | N27: O
D28: "111111111" | O28: O
A29: Confirm | B29: Return
D30: T | F30: O | G30: O | K30: O
D31: F | H31: O | I31: O | J31: O | L31: O | M31: O | N31: O | O31: O
B32: Exception
B34: Log message
D35: "update profile successfully" | F35: O | G35: O | K35: O
D36: "Name must be at least 1 character" | I36: O
D37: "Name must be <= 100 character" | H37: O
D38: "Name can not contain special character" | J38: O
D39: "Address must be <= 1000 character" | L39: O
D40: "Phone number must be start with 0" | M40: O
D41: "Phone number must be 10 numbers" | N41: O | O41: O
A42: Result | B42: Type(N : Normal, A : Abnormal, B : Boundary) | F42: N | G42: N | H42: B | I42: B | J42: A | K42: B | L42: B | M42: A | N42: B | O42: B
B43: Passed/Failed | F43: P | G43: P | H43: P | I43: P | J43: P | K43: P | L43: P | M43: F | N43: P | O43: P
B44: Executed Date | F44: 45590 | G44: 45590 | H44: 45590 | I44: 45590 | J44: 45590 | K44: 45590 | L44: 45590 | M44: 45590 | N44: 45590 | O44: 45590
...

Sheet Create Facility
A2: Function Code | C2: Create Facility | F2: Function Name | L2: Create Facility
A3: Created By | C3: KietHT | F3: Executed By | L3: KietHT
A4: Lines of code | C4: 300 | F4: Lack of test cases | L4: =IF(FunctionList!E6<>"N/A",SUM(C4*FunctionList!E6/1000,-O7),"N/A") -> 0.7
A5: Test requirement | C5: <Brief description about requirements which are tested in this function>
A6: Passed | C6: Failed | F6: Untested | L6: N/A/B | O6: Total Test Cases
A7: =COUNTIF(F50:HQ50,"P") -> 6 | C7: =COUNTIF(F50:HQ50,"F") -> 2 | F7: =SUM(O7,-A7,-C7) -> 0 | L7: =COUNTIF(E49:HQ49,"N") -> 2 | M7: =COUNTIF(E49:HQ49,"A") -> 6 | N7: =COUNTIF(E49:HQ49,"B") -> 0 | O7: =COUNTA(E9:HT9) -> 8
F9: UTCID01 | G9: UTCID02 | H9: UTCID03 | I9: UTCID04 | J9: UTCID05 | K9: UTCID06 | L9: UTCID07 | M9: UTCID08
A10: Condition | B10: Precondition
D11: Can connect with server | F11: O | G11: O | H11: O | I11: O | J11: O | K11: O | L11: O | M11: O
D12: User login with role admin | F12: O | G12: O | H12: O | I12: O | J12: O | K12: O | M12: O
B14: name ( Tối đa 100 ký tự )
D15: 100 ký tự | F15: O | M15: O
D16: 101 ký tự | G16: O
D17: "Phan Quang" | H17: O | I17: O | K17: O | L17: O
D18: "" | J18: O
B19: image ( <= 5MB )
D20: Ảnh 5MB | F20: O | G20: O | H20: O | I20: O | J20: O | M20: O
D21: Ảnh 6MB | K21: O
D22: Ảnh 4MB | L22: O
B23: status (0 và 1 )
D24: 0 | H24: O | I24: O | J24: O | M24: O
D25: 1 | F25: O | G25: O | K25: O | L25: O
B27: location ( Tối đa 1000 ký tự )
D28: 1000 ký tự | M28: O
D29: 1001 ký tự | H29: O
D30: Tòa Delta, Đại học FPT | F30: O | G30: O | J30: O | K30: O | L30: O
D31: "" | I31: O
A36: Confirm | B36: Return
D37: T | F37: O | M37: O
D38: F | G38: O | H38: O | I38: O | J38: O | K38: O | L38: O
B39: Exception
B41: Log message
D42: "success" | F42: O
D43: "Only admin can action with facility" | L43: O
D44: "Image can be exeed 5MB" | K44: O
D45: "Location cannot be empty" | I45: O
D46: "Name can not be empty" | J46: O
D47: "Max length of location is 1000" | H47: O
D48: "Max length of name is 100" | G48: O
A49: Result | B49: Type(N : Normal, A : Abnormal, B : Boundary) | F49: N | G49: A | H49: A | I49: A | J49: A | K49: A | L49: A | M49: N
...

Sheet Update Facility
A2: Function Code | C2: =FunctionList!E13 -> Create Facility | F2: Function Name | L2: =FunctionList!D13 -> Create Facility
A3: Created By | C3: KietHT | F3: Executed By | L3: KietHT
A4: Lines of code | C4: 300 | F4: Lack of test cases | L4: =IF(FunctionList!E6<>"N/A",SUM(C4*FunctionList!E6/1000,-O7),"N/A") -> 0.7
A5: Test requirement | C5: <Brief description about requirements which are tested in this function>
A6: Passed | C6: Failed | F6: Untested | L6: N/A/B | O6: Total Test Cases
A7: 7 | C7: 1 | F7: =SUM(O7,-A7,-C7) -> 0 | L7: 1 | M7: 4 | N7: 3 | O7: =COUNTA(E9:HT9) -> 8
F9: UTCID01 | G9: UTCID02 | H9: UTCID03 | I9: UTCID04 | J9: UTCID05 | K9: UTCID06 | L9: UTCID07 | M9: UTCID08
A10: Condition | B10: Precondition
D11: Can connect with server | F11: O | G11: O | H11: O | I11: O | J11: O | K11: O | L11: O | M11: O
D12: User login with role admin | F12: O | G12: O | H12: O | I12: O | J12: O | K12: O | M12: O
B14: name ( Tối đa 100 ký tự )
D15: 100 ký tự | F15: O | M15: O
D16: 101 ký tự | G16: O
D17: "Hoang Kiet" | H17: O | I17: O | K17: O | L17: O
D18: "" | J18: O
B19: image ( <= 5MB )
D20: Ảnh 5MB | F20: O | G20: O | H20: O | I20: O | J20: O | M20: O
D21: Ảnh 6MB | K21: O
D22: Ảnh 4MB | L22: O
B23: status (0 và 1 )
D24: 0 | H24: O | I24: O | J24: O | M24: O
D25: 1 | F25: O | G25: O | K25: O | L25: O
B27: location ( Tối đa 1000 ký tự )
D28: 1000 ký tự | M28: O
D29: 1001 ký tự | H29: O
D30: Tòa Delta, Đại học FPT | F30: O | G30: O | J30: O | K30: O | L30: O
D31: "" | I31: O
A36: Confirm | B36: Return
D37: T | F37: O | M37: O
D38: F | G38: O | H38: O | I38: O | J38: O | K38: O | L38: O
B39: Exception
B41: Log message
D42: "success" | F42: O
D43: "Only admin can action with facility" | L43: O
D44: "Image can be exeed 5MB" | K44: O
D45: "Location cannot be empty" | I45: O
D46: "Name can not be empty" | J46: O
D47: "Max length of location is 1000" | H47: O
D48: "Max length of name is 100" | G48: O
A49: Result | B49: Type(N : Normal, A : Abnormal, B : Boundary) | F49: N | G49: B | H49: B | I49: A | J49: A | K49: A | L49: A | M49: B
...
